Workbook

Sheet Features from steps
A1: User Journey | B1: 1. Unpack The Device | C1: 2. Open App | D1: 3. Scan QR Code | E1: 4. Secure Pairing | F1: 5. See Connection | G1: 6. Security Note | H1: 7. Use Device
A2: Feature 1 | B2: 1.1 Qr code on the device | C2: 2.1 Clickable App icon on mobile phone | D2: 3.1 Camera scanner | E2: 4.1 Run secure key exchange | F2: 5.1 Success confirmation | G2: 6.1 Security information pop-up | H2: 7.1 Connect/disconnect device
A3: Feature 2 | B3: 1.2 Instruction manual in the box | C3: 2.2 Main app screen | D3: 3.2 QR Detector | E3: 4.2 Establish encrypted communication | F3: 5.2 Add device to device map | G3: 6.2 Secure defaults | H3: 7.2 Show connection status
A4: Feature 3 | C4: 2.3 "Add device" button | D4: 3.3 Scan feedback | E4: 4.3 Retry pairing if needed | F4: 5.3 Show current status | G4: 6.3 Allow advanced security view | H4: 7.3 Basic security settings
A5: Feature 4 | C5: 2.4 Item list screen | D5: 3.4 Loading spinner | F5: 5.4 Load basic device profile | H5: 7.4 Advanced security settings
A6: Feature 5 | C6: 2.5 Bottom menu | F6: 5.5 Load advanced device profile
A11: In the scope of MVP
A12: Outside of the scope of MVP
A15: Device Firmware with Privacy-Tuned Smart Device Protocol | B15: 10. Set up device bluetooth | C15: 11. Exchange protocol keys | D15: 12. Exchange data and establish secure connection
A16: Feature 1 | B16: 10.1 Import device bluetooth settings | C16: 11.1 Generate keys based on device ID | D16: 12.1 Ensure keys exchange
A17: Feature 2 | B17: 10.2 Set up beacon | C17: 11.2 Send public keys to mobile phone application using bluetooth connection | D17: 12.2 Exchange handshake
A18: Feature 3 | B18: 10.3 Connection to mobile phone HomeGuard app | C18: 11.3 Receive session key | D18: 12.4 Check for connection stability
A19: Feature 4 | B19: 10.4 Energy management protocol | C19: 11.4 Differentiate keys between different connection types | D19: 12.5 Implement connection stability improvement algorithm
A20: Feature 5 | C20: 11.5 Send different keys based on connection type

Sheet Initial US from features
A1: Story | B1: Enabler
A2: Step | B2: ID | C2: Name | D2: User Story | E2: Acceptance Criteria
A3: =Tabela2[[#Headers],[1. Unpack The Device]] -> 1. Unpack The Device | B3: US1.1 | C3: ='Features from steps'!B2 -> 1.1 Qr code on the device | D3: As a user, I want the device to have a QR code so that I can scan it easily. | E3: Given the user unpacks the device When they look at it Then a QR code is visible and scannable
A4: =Tabela2[[#Headers],[1. Unpack The Device]] -> 1. Unpack The Device | B4: US1.2 | C4: ='Features from steps'!B3 -> 1.2 Instruction manual in the box | D4: As a user, I want an instruction manual so that I know how to begin onboarding. | E4: Given the device is unpacked When the user reads the manual Then steps direct them to the app and QR code
A5: =Tabela2[[#Headers],[2. Open App]] -> 2. Open App | B5: US2.1 | C5: ='Features from steps'!C2 -> 2.1 Clickable App icon on mobile phone | D5: As a user, I want a visible app icon so that I can open the HomeGuard app easily. | E5: Given the app is installed When the user views the home screen Then the icon is visible and tappable
A6: =Tabela2[[#Headers],[2. Open App]] -> 2. Open App | B6: US2.2 | C6: ='Features from steps'!C3 -> 2.2 Main app screen | D6: As a user, I want a main screen so that I can perform actions in HomeGuard app. | E6: Given the HomeGuard app is installed When the user opens the app Then the main screen appears
A7: =Tabela2[[#Headers],[2. Open App]] -> 2. Open App | B7: US2.3 | C7: ='Features from steps'!C4 -> 2.3 "Add device" button | D7: As a user, I want an Add Device button so that I can start onboarding quickly. | E7: Given the user is on the home screen When they click Add Device Then onboarding starts
A8: =Tabela2[[#Headers],[2. Open App]] -> 2. Open App | B8: US2.4 | C8: ='Features from steps'!C5 -> 2.4 Item list screen | D8: As a user, I want to see the list of my devices so that I know which devices are connected with secure protocol. | E8: Given the user has the HomeGuard application opened When the main screen is opened Then the device list is visible And the devices connected are shown
A9: =Tabela2[[#Headers],[2. Open App]] -> 2. Open App | B9: US2.5 | C9: ='Features from steps'!C6 -> 2.5 Bottom menu | D9: As a user, I want a bottom menu so that I can navigate through the application screens. | E9: Given HomeGuard application is opened When the user looks at the bottom of any screen Then the bottom menu is visible Given HomeGuard application is opened When user clicks on any bottom menu item Then the connected screen open
A10: =Tabela2[[#Headers],[3. Scan QR Code]] -> 3. Scan QR Code | B10: US3.1 | C10: ='Features from steps'!D2 -> 3.1 Camera scanner | D10: As a user, I want the camera scanner to open so that I can scan the QR code. | E10: Given HomeGuard app is opened When add device button is clicked Then camera view opens
A11: =Tabela2[[#Headers],[3. Scan QR Code]] -> 3. Scan QR Code | B11: US3.2 | C11: ='Features from steps'!D3 -> 3.2 QR Detector | D11: As a user, I want QR detection so that onboarding continues quickly. | E11: Given the camera is opened When the QR code is visible Then camera scans the QR code
A12: =Tabela2[[#Headers],[3. Scan QR Code]] -> 3. Scan QR Code | B12: US3.3 | C12: ='Features from steps'!D4 -> 3.3 Scan feedback | D12: As a user, I want confirmation of successful scan so that I know to continue. | E12: Given the QR is scanned When it is successful Then confirmation appears And camera closes Given the QR is scanned When it is wrong Then window with information appears And camera closes
A13: =Tabela2[[#Headers],[3. Scan QR Code]] -> 3. Scan QR Code | B13: US3.4 | C13: ='Features from steps'!D5 -> 3.4 Loading spinner | D13: As a user, I want a loading spinner so that I know the scan is being processes and I am not impatient. | E13: Given scanning is attempted When QR information is being processed Then the loading spinner is visible
A14: =Tabela2[[#Headers],[4. Secure Pairing]] -> 4. Secure Pairing | B14: E4.1 | C14: ='Features from steps'!E2 -> 4.1 Run secure key exchange | D14: As a developer, I want pairing to run the key exchange so that I will be able to show the user that the device connects securely. | E14: Given QR scan succeeded When pairing starts Then key exchange begins Given pairing begins When key exchange runs Then no input is needed And data is safely processed
A15: =Tabela2[[#Headers],[4. Secure Pairing]] -> 4. Secure Pairing | B15: E4.2 | C15: ='Features from steps'!E3 -> 4.2 Establish encrypted communication | D15: As a developer, I want cryptographic exchange handled automatically so that I can create visual output to the user. | E15: Given pairing begins When key exchange runs Then no input is needed
A16: =Tabela2[[#Headers],[4. Secure Pairing]] -> 4. Secure Pairing | B16: E4.3 | C16: ='Features from steps'!E4 -> 4.3 Retry pairing if needed | D16: As a developer I want retry option so that pairing failures can be fixed. | E16: Given pairing fails When error occurs Then it is retried
A17: =Tabela2[[#Headers],[5. See Connection]] -> 5. See Connection | B17: US5.1 | C17: ='Features from steps'!F2 -> 5.1 Success confirmation | D17: As a user I want to see a confirmation in HomeGuard app so that I know my data was correctly encrypted and the connection is secure. | E17: Given device onboarding is in process When the connection was established Then the success confirmation is displayed
A18: =Tabela2[[#Headers],[5. See Connection]] -> 5. See Connection | B18: US5.2 | C18: ='Features from steps'!F3 -> 5.2 Add device to device map | D18: As a user, I want the device added to the map so that I see it in my network. | E18: Given device connected When map refreshes Then device appears
A19: =Tabela2[[#Headers],[5. See Connection]] -> 5. See Connection | B19: US5.3 | C19: ='Features from steps'!F4 -> 5.3 Show current status | D19: As a user, I want basic info so that I can recognize the device. | E19: Given Homeguard app is opened When a device is visible on the list Then the status is displayed
A20: =Tabela2[[#Headers],[5. See Connection]] -> 5. See Connection | B20: US5.4 | C20: ='Features from steps'!F5 -> 5.4 Load basic device profile | D20: Load basic device profile | E20: Given HomeGuard app opened When user clicks the device Then basic device information is displayed
A21: =Tabela2[[#Headers],[5. See Connection]] -> 5. See Connection | B21: US5.5 | C21: ='Features from steps'!F6 -> 5.5 Load advanced device profile | D21: As a user, I want advanced info so that I can analyze the device performance. | E21: Given HomeGuard app opened When user clicks the device Then basic device information is displayed And the advanced information is displayed below
A22: =Tabela2[[#Headers],[6. Security Note]] -> 6. Security Note | B22: US6.1 | C22: ='Features from steps'!G2 -> 6.1 Security information pop-up | D22: As a user, I want a security note so that I understand that my IoT network is secure. | E22: Given device connected When device type recognized Then security note shows
A23: =Tabela2[[#Headers],[6. Security Note]] -> 6. Security Note | B23: US6.2 | C23: ='Features from steps'!G3 -> 6.2 Secure defaults | D23: As a user, I want secure defaults so that my device is protected fast. | E23: Given recommendation shown When user taps secure defaults Then settings apply
A24: =Tabela2[[#Headers],[6. Security Note]] -> 6. Security Note | B24: US6.3 | C24: ='Features from steps'!G4 -> 6.3 Allow advanced security view | D24: As a user, I want advanced security options so that I can customize behavior. | E24: Given advanced view selected When advanced settings open Then user can modify permissions
A25: =Tabela2[[#Headers],[7. Use Device]] -> 7. Use Device | B25: US7.1 | C25: ='Features from steps'!H2 -> 7.1 Connect/disconnect device | D25: As a user I want to be able to manage device connection so that I can connect or disconnect based on my needs. | E25: Given device in the list When I click connection button Then device status is updated
A26: =Tabela2[[#Headers],[7. Use Device]] -> 7. Use Device | B26: US7.2 | C26: ='Features from steps'!H3 -> 7.2 Show connection status | D26: As a user I want to be able to see device connection status so that I know if I need to connect or disconnect. | E26: Given HomeGuard app opened When device is on the list Then the connection status is shown
A27: =Tabela2[[#Headers],[7. Use Device]] -> 7. Use Device | B27: US7.3 | C27: ='Features from steps'!H4 -> 7.3 Basic security settings | D27: As a user I want to have ability to change basic security settings so that i can configure the device to my needs. | E27: Given HomeGuard app opened And device is on the list When the user clicks the device Then there is a button to change security settings And basic security settings are shown
A28: =Tabela2[[#Headers],[7. Use Device]] -> 7. Use Device | B28: US7.4 | C28: ='Features from steps'!H5 -> 7.4 Advanced security settings | D28: As a user I want to have ability to change advanced security settings so that i can configure the device deeply to my needs. | E28: Given HomeGuard app opened And device is on the list When the user clicks the device Then there is a button to change security settings And advanced security settings are shown under basic security settings
A29: =Tabela3[[#Headers],[10. Set up device bluetooth]] -> 10. Set up device bluetooth | B29: E10.1 | C29: ='Features from steps'!B16 -> 10.1 Import device bluetooth settings | E29: Given device is ON When the firmware runs Then the device bluetooth module is running and firmware has control over it
A30: =Tabela3[[#Headers],[10. Set up device bluetooth]] -> 10. Set up device bluetooth | B30: E10.2 | C30: ='Features from steps'!B17 -> 10.2 Set up beacon | E30: Given device is ON When the firmware runs Then the device is listening for communication from the mobile app
A31: =Tabela3[[#Headers],[10. Set up device bluetooth]] -> 10. Set up device bluetooth | B31: E10.3 | C31: ='Features from steps'!B18 -> 10.3 Connection to mobile phone HomeGuard app | E31: Given the firmware running When the request from mobile app comes Then the bluetooth connection is established
A32: =Tabela3[[#Headers],[10. Set up device bluetooth]] -> 10. Set up device bluetooth | B32: E10.4 | C32: ='Features from steps'!B19 -> 10.4 Energy management protocol | E32: Given established connection When data is not exchanged Then energy saving protocol is running
A33: =Tabela3[[#Headers],[11. Exchange protocol keys]] -> 11. Exchange protocol keys | B33: E11.1 | C33: ='Features from steps'!C16 -> 11.1 Generate keys based on device ID | E33: Given bluetooth connection established When data exchange is requested Then keys are generated
A34: =Tabela3[[#Headers],[11. Exchange protocol keys]] -> 11. Exchange protocol keys | B34: E11.2 | C34: ='Features from steps'!C17 -> 11.2 Send public keys to mobile phone application using bluetooth connection | E34: Given keys generated When data echange is requested Then the public key is exchanged with the HomeGuard app
A35: =Tabela3[[#Headers],[11. Exchange protocol keys]] -> 11. Exchange protocol keys | B35: E11.3 | C35: ='Features from steps'!C18 -> 11.3 Receive session key | E35: Given connection established When public key is received by HomeGuard Then session key is sent by HomeGuard and validated by the device
A36: =Tabela3[[#Headers],[11. Exchange protocol keys]] -> 11. Exchange protocol keys | B36: E11.4 | C36: ='Features from steps'!C19 -> 11.4 Differentiate keys between different connection types | E36: Given a connection type different than bluetooth When a key is generated Then the keys are different as for the different connection needs
A37: =Tabela3[[#Headers],[11. Exchange protocol keys]] -> 11. Exchange protocol keys | B37: E11.5 | C37: ='Features from steps'!C20 -> 11.5 Send different keys based on connection type | E37: Given a connection type different than bluetooth When a key is exchanged Then the keys are different as for the different connection needs
A38: =Tabela3[[#Headers],[12. Exchange data and establish secure connection]] -> 12. Exchange data and establish secure connection | B38: E12.1 | C38: ='Features from steps'!D16 -> 12.1 Ensure keys exchange | E38: Given the bluetooth connection established When the exchanged keys are correct Then the connection is set as secure
A39: =Tabela3[[#Headers],[12. Exchange data and establish secure connection]] -> 12. Exchange data and establish secure connection | B39: E12.2 | C39: ='Features from steps'!D17 -> 12.2 Exchange handshake | E39: Given the bluetooth connection established When the connection is set as secure Then the handshake is exchanged between the device and HomeGuard app
A40: =Tabela3[[#Headers],[12. Exchange data and establish secure connection]] -> 12. Exchange data and establish secure connection | B40: E12.3 | C40: ='Features from steps'!D18 -> 12.4 Check for connection stability | E40: Given the bluetooth connection established When the connection is set as secure Then the connection stability status is being calculated
...
